Workbook

Sheet Instructions
B2: RFP Vendor Assessment
B3: MoSCoW-weighted scoring model
B5: How it works
B6: 1. Set your criteria | C6: On the 'Assessment' tab, list every requirement from your RFP. Group them with a Category if useful.
B7: 2. Assign MoSCoW | C7: For each requirement pick a priority from the dropdown: Must, Should, Could, or Won't. This drives the weight automatically.
B8: 3. Score each vendor | C8: Rate every vendor 0-5 against each requirement using the dropdown. The rating scale is on the 'Config' tab.
B9: 4. Read the result | C9: The 'Results' tab ranks vendors by weighted score (%), and flags any vendor that fails a Must-have.
B11: The maths
B12: Weight | C12: Each MoSCoW level maps to a weight (Config tab, editable). Default: Must=5, Should=3, Could=1, Won't=0.
B13: Weighted score | C13: For each requirement: Weight x Vendor score (0-5). Shown per vendor on the Assessment tab.
B14: Total & % | C14: A vendor's total is the sum of its weighted scores. The % is total / maximum possible (every weight scored 5).
B15: Must-have gate | C15: Any Must scored below the pass threshold (Config, default 3) fails the vendor regardless of overall %. This is the RFP shortlist gate.
B17: Colour key
B18: Yellow cells | C18: You edit these (criteria text, MoSCoW level, vendor scores, vendor names).
B19: White/grey cells | C19: Calculated for you. Leave them alone.
B20: Config tab | C20: Change the MoSCoW weights, rating-scale labels, or the Must-have pass threshold here. Everything recalculates.

Sheet Config
B2: Configuration
B3: Edit the yellow cells to retune the model. Everything else follows.
B5: MoSCoW weighting
B6: MoSCoW level | C6: Weight | D6: Meaning
B7: Must | C7: 5 | D7: Mandatory. Non-negotiable requirement; failing it should disqualify a vendor.
B8: Should | C8: 3 | D8: High priority. Important but not vital; a workaround may exist.
B9: Could | C9: 1 | D9: Desirable. Nice to have if it does not affect cost or timeline much.
B10: Won't | C10: 0 | D10: Out of scope for now. Recorded but scores nothing.
B12: Must-have pass threshold
B13: Minimum score (0-5) a vendor must reach on every Must-have requirement: | D13: 3
B15: Rating scale (how well a vendor meets a requirement)
B16: Score | C16: Label | D16: Guidance
B17: 5 | C17: Excellent | D17: Fully meets and exceeds the requirement; best in class.
B18: 4 | C18: Good | D18: Fully meets the requirement out of the box.
B19: 3 | C19: Adequate | D19: Meets the requirement with minor gaps or config.
B20: 2 | C20: Partial | D20: Partially meets; notable gaps or customisation needed.
B21: 1 | C21: Poor | D21: Barely addresses the requirement; heavy workaround.
B22: 0 | C22: Not met | D22: Does not meet the requirement at all.

Sheet Assessment
A1: Vendor Assessment
A2: Yellow = you edit. Pick MoSCoW and score each vendor 0-5. Weight and weighted scores are automatic.
A4: Enter vendor names >> | G4: Vendor A | I4: Vendor B | K4: Vendor C | M4: Vendor D | O4: VegaIT layer | P4: Why this is marked
A5: ID | B5: Category | C5: Requirement | D5: MoSCoW | E5: Weight | G5: Score | H5: Weighted | I5: Score | J5: Weighted | K5: Score | L5: Weighted | M5: Score | N5: Weighted
A6: TEL-01 | B6: Telephony & call routing | C6: Integrates with the existing phone systems (multiple Mitel products supported by Maintel) | D6: Must | E6: {=IFERROR(INDEX(Config!$C$7:$C$10,MATCH(D6,Config!$B$7:$B$10,0)),0)} -> 5 | G6: 5 | H6: =IF(G6="","",$E6*G6) -> 25 | I6: 3 | J6: =IF(I6="","",$E6*I6) -> 15 | K6: 4 | L6: =IF(K6="","",$E6*K6) -> 20 | M6: 2 | N6: =IF(M6="","",$E6*M6) -> 10
A7: TEL-02 | B7: Telephony & call routing | C7: Can operate as the primary phone answering system, or pick up calls on configurable thresholds (e.g. rings, queue time, out of hours) | D7: Must | E7: {=IFERROR(INDEX(Config!$C$7:$C$10,MATCH(D7,Config!$B$7:$B$10,0)),0)} -> 5 | G7: 4 | H7: =IF(G7="","",$E7*G7) -> 20 | I7: 4 | J7: =IF(I7="","",$E7*I7) -> 20 | K7: 3 | L7: =IF(K7="","",$E7*K7) -> 15 | M7: 5 | N7: =IF(M7="","",$E7*M7) -> 25
A8: TEL-03 | B8: Telephony & call routing | C8: Queue management and routing for calls not handled by the AI | D8: Must | E8: {=IFERROR(INDEX(Config!$C$7:$C$10,MATCH(D8,Config!$B$7:$B$10,0)),0)} -> 5 | G8: 5 | H8: =IF(G8="","",$E8*G8) -> 25 | I8: 2 | J8: =IF(I8="","",$E8*I8) -> 10 | K8: 4 | L8: =IF(K8="","",$E8*K8) -> 20 | M8: 3 | N8: =IF(M8="","",$E8*M8) -> 15
A9: TEL-04 | B9: Telephony & call routing | C9: Outbound calls and cold calling capability | D9: Must | E9: {=IFERROR(INDEX(Config!$C$7:$C$10,MATCH(D9,Config!$B$7:$B$10,0)),0)} -> 5 | G9: 3 | H9: =IF(G9="","",$E9*G9) -> 15 | I9: 4 | J9: =IF(I9="","",$E9*I9) -> 20 | K9: 2 | L9: =IF(K9="","",$E9*K9) -> 10 | M9: 4 | N9: =IF(M9="","",$E9*M9) -> 20
A10: TEL-05 | B10: Telephony & call routing | C10: Handles peak concurrent call volumes across all practices and support centres without degradation; vendor states capacity limits | D10: Must | E10: {=IFERROR(INDEX(Config!$C$7:$C$10,MATCH(D10,Config!$B$7:$B$10,0)),0)} -> 5 | G10: 4 | H10: =IF(G10="","",$E10*G10) -> 20 | I10: 3 | J10: =IF(I10="","",$E10*I10) -> 15 | K10: 5 | L10: =IF(K10="","",$E10*K10) -> 25 | M10: 3 | N10: =IF(M10="","",$E10*M10) -> 15
A11: TEL-06 | B11: Telephony & call routing | C11: Central administration of per-practice configuration (numbers, opening hours, services, journeys) without per-site vendor work | D11: Must | E11: {=IFERROR(INDEX(Config!$C$7:$C$10,MATCH(D11,Config!$B$7:$B$10,0)),0)} -> 5 | G11: 3 | H11: =IF(G11="","",$E11*G11) -> 15 | I11: 5 | J11: =IF(I11="","",$E11*I11) -> 25 | K11: 4 | L11: =IF(K11="","",$E11*K11) -> 20 | M11: 2 | N11: =IF(M11="","",$E11*M11) -> 10
A12: TEL-07 | B12: Telephony & call routing | C12: Out-of-hours and overflow handling with configurable schedules per practice | D12: Must | E12: {=IFERROR(INDEX(Config!$C$7:$C$10,MATCH(D12,Config!$B$7:$B$10,0)),0)} -> 5 | H12: =IF(G12="","",$E12*G12) | J12: =IF(I12="","",$E12*I12) | L12: =IF(K12="","",$E12*K12) | N12: =IF(M12="","",$E12*M12)
A13: TEL-08 | B13: Telephony & call routing | C13: Call recording with configurable retention, retrievable per call | D13: Must | E13: {=IFERROR(INDEX(Config!$C$7:$C$10,MATCH(D13,Config!$B$7:$B$10,0)),0)} -> 5 | H13: =IF(G13="","",$E13*G13) | J13: =IF(I13="","",$E13*I13) | L13: =IF(K13="","",$E13*K13) | N13: =IF(M13="","",$E13*M13) | O13: Gate | P13: Recording either exists with retrievable retention or it does not, and its absence blocks the consent and audit design.
A14: TEL-09 | B14: Telephony & call routing | C14: Keypad (DTMF) fallback for callers who cannot or will not speak to the AI | D14: Must | E14: {=IFERROR(INDEX(Config!$C$7:$C$10,MATCH(D14,Config!$B$7:$B$10,0)),0)} -> 5 | H14: =IF(G14="","",$E14*G14) | J14: =IF(I14="","",$E14*I14) | L14: =IF(K14="","",$E14*K14) | N14: =IF(M14="","",$E14*M14)
A15: CNV-01 | B15: Conversation & voice experience | C15: Low latency so the conversation feels as natural as possible | D15: Must | E15: {=IFERROR(INDEX(Config!$C$7:$C$10,MATCH(D15,Config!$B$7:$B$10,0)),0)} -> 5 | H15: =IF(G15="","",$E15*G15) | J15: =IF(I15="","",$E15*I15) | L15: =IF(K15="","",$E15*K15) | N15: =IF(M15="","",$E15*M15)
A16: CNV-02 | B16: Conversation & voice experience | C16: Conversational responsiveness: adjusts speed and tone of voice to match the caller | D16: Should | E16: {=IFERROR(INDEX(Config!$C$7:$C$10,MATCH(D16,Config!$B$7:$B$10,0)),0)} -> 3 | H16: =IF(G16="","",$E16*G16) | J16: =IF(I16="","",$E16*I16) | L16: =IF(K16="","",$E16*K16) | N16: =IF(M16="","",$E16*M16)
A17: CNV-03 | B17: Conversation & voice experience | C17: Multi-language support (Welsh and English) | D17: Must | E17: {=IFERROR(INDEX(Config!$C$7:$C$10,MATCH(D17,Config!$B$7:$B$10,0)),0)} -> 5 | H17: =IF(G17="","",$E17*G17) | J17: =IF(I17="","",$E17*I17) | L17: =IF(K17="","",$E17*K17) | N17: =IF(M17="","",$E17*M17)
A18: CNV-04 | B18: Conversation & voice experience | C18: Multi-language support (other languages) | D18: Could | E18: {=IFERROR(INDEX(Config!$C$7:$C$10,MATCH(D18,Config!$B$7:$B$10,0)),0)} -> 1 | H18: =IF(G18="","",$E18*G18) | J18: =IF(I18="","",$E18*I18) | L18: =IF(K18="","",$E18*K18) | N18: =IF(M18="","",$E18*M18)
A19: CNV-05 | B19: Conversation & voice experience | C19: Ability to change voice (male / female) | D19: Could | E19: {=IFERROR(INDEX(Config!$C$7:$C$10,MATCH(D19,Config!$B$7:$B$10,0)),0)} -> 1 | H19: =IF(G19="","",$E19*G19) | J19: =IF(I19="","",$E19*I19) | L19: =IF(K19="","",$E19*K19) | N19: =IF(M19="","",$E19*M19)
A20: CNV-06 | B20: Conversation & voice experience | C20: Multiple regional accents | D20: Could | E20: {=IFERROR(INDEX(Config!$C$7:$C$10,MATCH(D20,Config!$B$7:$B$10,0)),0)} -> 1 | H20: =IF(G20="","",$E20*G20) | J20: =IF(I20="","",$E20*I20) | L20: =IF(K20="","",$E20*K20) | N20: =IF(M20="","",$E20*M20)
A21: CNV-07 | B21: Conversation & voice experience | C21: Ability to change the accent based on the CLI or ID verification | D21: Could | E21: {=IFERROR(INDEX(Config!$C$7:$C$10,MATCH(D21,Config!$B$7:$B$10,0)),0)} -> 1 | H21: =IF(G21="","",$E21*G21) | J21: =IF(I21="","",$E21*I21) | L21: =IF(K21="","",$E21*K21) | N21: =IF(M21="","",$E21*M21)
A22: CNV-08 | B22: Conversation & voice experience | C22: Discloses to the caller at the start of the call that they are speaking to an AI, and how to reach a person | D22: Must | E22: {=IFERROR(INDEX(Config!$C$7:$C$10,MATCH(D22,Config!$B$7:$B$10,0)),0)} -> 5 | H22: =IF(G22="","",$E22*G22) | J22: =IF(I22="","",$E22*I22) | L22: =IF(K22="","",$E22*K22) | N22: =IF(M22="","",$E22*M22) | O22: Gate | P22: Either the agent discloses that it is AI or it does not. A partial disclosure has no meaning.
A23: CNV-09 | B23: Conversation & voice experience | C23: Handles interruptions (barge-in), pauses and background noise without losing the thread | D23: Must | E23: {=IFERROR(INDEX(Config!$C$7:$C$10,MATCH(D23,Config!$B$7:$B$10,0)),0)} -> 5 | H23: =IF(G23="","",$E23*G23) | J23: =IF(I23="","",$E23*I23) | L23: =IF(K23="","",$E23*K23) | N23: =IF(M23="","",$E23*M23)
A24: CNV-10 | B24: Conversation & voice experience | C24: Recognises when it has not understood and re-prompts or hands off rather than guessing | D24: Must | E24: {=IFERROR(INDEX(Config!$C$7:$C$10,MATCH(D24,Config!$B$7:$B$10,0)),0)} -> 5 | H24: =IF(G24="","",$E24*G24) | J24: =IF(I24="","",$E24*I24) | L24: =IF(K24="","",$E24*K24) | N24: =IF(M24="","",$E24*M24)
A25: IDV-01 | B25: Caller identification & verification | C25: ID verification: takes call data that identifies the individual and matches it to our patient record | D25: Must | E25: {=IFERROR(INDEX(Config!$C$7:$C$10,MATCH(D25,Config!$B$7:$B$10,0)),0)} -> 5 | H25: =IF(G25="","",$E25*G25) | J25: =IF(I25="","",$E25*I25) | L25: =IF(K25="","",$E25*K25) | N25: =IF(M25="","",$E25*M25) | O25: Out of scope | P25: Matching a caller to the patient record happens in our identity resolution service against the CDP, not in the voice runtime.
A26: IDV-02 | B26: Caller identification & verification | C26: Records CLI and uses it as a seed for ID verification | D26: Must | E26: {=IFERROR(INDEX(Config!$C$7:$C$10,MATCH(D26,Config!$B$7:$B$10,0)),0)} -> 5 | H26: =IF(G26="","",$E26*G26) | J26: =IF(I26="","",$E26*I26) | L26: =IF(K26="","",$E26*K26) | N26: =IF(M26="","",$E26*M26)
A27: IDV-03 | B27: Caller identification & verification | C27: Integrates with our ID verification pathway | D27: Must | E27: {=IFERROR(INDEX(Config!$C$7:$C$10,MATCH(D27,Config!$B$7:$B$10,0)),0)} -> 5 | H27: =IF(G27="","",$E27*G27) | J27: =IF(I27="","",$E27*I27) | L27: =IF(K27="","",$E27*K27) | N27: =IF(M27="","",$E27*M27) | O27: Out of scope | P27: Our ID verification pathway is orchestration layer logic, so every vendor would score identically.
A28: IDV-04 | B28: Caller identification & verification | C28: Identifies and distinguishes between patients and other services that interact with practices or our support centres (e.g. clinicians, labs) | D28: Must | E28: {=IFERROR(INDEX(Config!$C$7:$C$10,MATCH(D28,Config!$B$7:$B$10,0)),0)} -> 5 | H28: =IF(G28="","",$E28*G28) | J28: =IF(I28="","",$E28*I28) | L28: =IF(K28="","",$E28*K28) | N28: =IF(M28="","",$E28*M28) | O28: Split | P28: Conversational classification of caller type is a vendor capability, but matching to records is ours. Split before scoring.
A29: IDV-05 | B29: Caller identification & verification | C29: Asks the caller whether they have any specific requirements and records the answer to other systems | D29: Must | E29: {=IFERROR(INDEX(Config!$C$7:$C$10,MATCH(D29,Config!$B$7:$B$10,0)),0)} -> 5 | H29: =IF(G29="","",$E29*G29) | J29: =IF(I29="","",$E29*I29) | L29: =IF(K29="","",$E29*K29) | N29: =IF(M29="","",$E29*M29)
A30: IDV-06 | B30: Caller identification & verification | C30: Handles third-party callers (parent/guardian, carer, someone calling on behalf of a patient) with appropriate authority checks | D30: Must | E30: {=IFERROR(INDEX(Config!$C$7:$C$10,MATCH(D30,Config!$B$7:$B$10,0)),0)} -> 5 | H30: =IF(G30="","",$E30*G30) | J30: =IF(I30="","",$E30*I30) | L30: =IF(K30="","",$E30*K30) | N30: =IF(M30="","",$E30*M30) | O30: Split | P30: Handling a third party caller conversationally is vendor work, but the authority check against the record is ours.
A31: IDV-07 | B31: Caller identification & verification | C31: Verification strength is configurable by transaction type (e.g. booking vs. discussing appointment detail vs. payment) | D31: Should | E31: {=IFERROR(INDEX(Config!$C$7:$C$10,MATCH(D31,Config!$B$7:$B$10,0)),0)} -> 3 | H31: =IF(G31="","",$E31*G31) | J31: =IF(I31="","",$E31*I31) | L31: =IF(K31="","",$E31*K31) | N31: =IF(M31="","",$E31*M31)
A32: JRN-01 | B32: Journey design & workflow orchestration | C32: Configurable and responsive customer journey through the call interaction | D32: Must | E32: {=IFERROR(INDEX(Config!$C$7:$C$10,MATCH(D32,Config!$B$7:$B$10,0)),0)} -> 5 | H32: =IF(G32="","",$E32*G32) | J32: =IF(I32="","",$E32*I32) | L32: =IF(K32="","",$E32*K32) | N32: =IF(M32="","",$E32*M32)
A33: JRN-02 | B33: Journey design & workflow orchestration | C33: Ability to have multiple workflows | D33: Must | E33: {=IFERROR(INDEX(Config!$C$7:$C$10,MATCH(D33,Config!$B$7:$B$10,0)),0)} -> 5 | H33: =IF(G33="","",$E33*G33) | J33: =IF(I33="","",$E33*I33) | L33: =IF(K33="","",$E33*K33) | N33: =IF(M33="","",$E33*M33)
A34: JRN-03 | B34: Journey design & workflow orchestration | C34: Ability to interact with and drive workflow in other tools | D34: Should | E34: {=IFERROR(INDEX(Config!$C$7:$C$10,MATCH(D34,Config!$B$7:$B$10,0)),0)} -> 3 | H34: =IF(G34="","",$E34*G34) | J34: =IF(I34="","",$E34*I34) | L34: =IF(K34="","",$E34*K34) | N34: =IF(M34="","",$E34*M34)
A35: JRN-04 | B35: Journey design & workflow orchestration | C35: Intent recognition covering core dental use cases: book, amend, cancel, emergency, treatment/price enquiry, payment, complaint, general enquiry | D35: Must | E35: {=IFERROR(INDEX(Config!$C$7:$C$10,MATCH(D35,Config!$B$7:$B$10,0)),0)} -> 5 | H35: =IF(G35="","",$E35*G35) | J35: =IF(I35="","",$E35*I35) | L35: =IF(K35="","",$E35*K35) | N35: =IF(M35="","",$E35*M35)
A36: JRN-05 | B36: Journey design & workflow orchestration | C36: Journeys, prompts and knowledge editable by trained mydentist staff without vendor change requests (low-code / no-code) | D36: Should | E36: {=IFERROR(INDEX(Config!$C$7:$C$10,MATCH(D36,Config!$B$7:$B$10,0)),0)} -> 3 | H36: =IF(G36="","",$E36*G36) | J36: =IF(I36="","",$E36*I36) | L36: =IF(K36="","",$E36*K36) | N36: =IF(M36="","",$E36*M36)
A37: JRN-06 | B37: Journey design & workflow orchestration | C37: Test environment and version control for journey changes before release to live | D37: Must | E37: {=IFERROR(INDEX(Config!$C$7:$C$10,MATCH(D37,Config!$B$7:$B$10,0)),0)} -> 5 | H37: =IF(G37="","",$E37*G37) | J37: =IF(I37="","",$E37*I37) | L37: =IF(K37="","",$E37*K37) | N37: =IF(M37="","",$E37*M37)
A38: HND-01 | B38: Human hand-off & escalation | C38: Patients have a clear 'off ramp' to speak directly to a human | D38: Must | E38: {=IFERROR(INDEX(Config!$C$7:$C$10,MATCH(D38,Config!$B$7:$B$10,0)),0)} -> 5 | H38: =IF(G38="","",$E38*G38) | J38: =IF(I38="","",$E38*I38) | L38: =IF(K38="","",$E38*K38) | N38: =IF(M38="","",$E38*M38) | O38: Gate | P38: A caller either has a route to a human or they do not.
A39: HND-02 | B39: Human hand-off & escalation | C39: Hands over to a human based on specific criteria or when it is not able to help | D39: Must | E39: {=IFERROR(INDEX(Config!$C$7:$C$10,MATCH(D39,Config!$B$7:$B$10,0)),0)} -> 5 | H39: =IF(G39="","",$E39*G39) | J39: =IF(I39="","",$E39*I39) | L39: =IF(K39="","",$E39*K39) | N39: =IF(M39="","",$E39*M39)
A40: HND-03 | B40: Human hand-off & escalation | C40: Hands over to a human based on semantic analysis and view of emotive level | D40: Could | E40: {=IFERROR(INDEX(Config!$C$7:$C$10,MATCH(D40,Config!$B$7:$B$10,0)),0)} -> 1 | H40: =IF(G40="","",$E40*G40) | J40: =IF(I40="","",$E40*I40) | L40: =IF(K40="","",$E40*K40) | N40: =IF(M40="","",$E40*M40)
A41: HND-04 | B41: Human hand-off & escalation | C41: Recognises dental emergencies and safeguarding concerns and routes them via a defined pathway, not a generic queue | D41: Should | E41: {=IFERROR(INDEX(Config!$C$7:$C$10,MATCH(D41,Config!$B$7:$B$10,0)),0)} -> 3 | H41: =IF(G41="","",$E41*G41) | J41: =IF(I41="","",$E41*I41) | L41: =IF(K41="","",$E41*K41) | N41: =IF(M41="","",$E41*M41)
...

Sheet Results
B2: Results Dashboard
B3: Ranked by weighted score. A Must-have gate failure overrides the ranking for shortlisting.
B5: Rank | C5: Vendor | D5: Weighted score | E5: Max possible | F5: Score % | G5: Must gate | H5: Recommendation
B6: =IF(E6=0,"",RANK(F6,$F$6:$F$9,0)) -> 1 | C6: =Assessment!G4 -> Vendor A | D6: =Assessment!G95 -> 120 | E6: =Assessment!G96 -> 150 | F6: =Assessment!G97 -> 0.8 | G6: =Assessment!G98 -> PASS | H6: =IF(E6=0,"Not scored",IF(G6="FAIL","Excluded - fails a Must",IF(B6=1,"Preferred","Consider"))) -> Preferred
B7: =IF(E7=0,"",RANK(F7,$F$6:$F$9,0)) -> 3 | C7: =Assessment!I4 -> Vendor B | D7: =Assessment!I95 -> 105 | E7: =Assessment!I96 -> 150 | F7: =Assessment!I97 -> 0.7 | G7: =Assessment!I98 -> FAIL | H7: =IF(E7=0,"Not scored",IF(G7="FAIL","Excluded - fails a Must",IF(B7=1,"Preferred","Consider"))) -> Excluded - fails a Must
B8: =IF(E8=0,"",RANK(F8,$F$6:$F$9,0)) -> 2 | C8: =Assessment!K4 -> Vendor C | D8: =Assessment!K95 -> 110 | E8: =Assessment!K96 -> 150 | F8: =Assessment!K97 -> 0.73333333 | G8: =Assessment!K98 -> FAIL | H8: =IF(E8=0,"Not scored",IF(G8="FAIL","Excluded - fails a Must",IF(B8=1,"Preferred","Consider"))) -> Excluded - fails a Must
B9: =IF(E9=0,"",RANK(F9,$F$6:$F$9,0)) -> 4 | C9: =Assessment!M4 -> Vendor D | D9: =Assessment!M95 -> 95 | E9: =Assessment!M96 -> 150 | F9: =Assessment!M97 -> 0.63333333 | G9: =Assessment!M98 -> FAIL | H9: =IF(E9=0,"Not scored",IF(G9="FAIL","Excluded - fails a Must",IF(B9=1,"Preferred","Consider"))) -> Excluded - fails a Must
B11: Notes
B12: Score % = total weighted score / maximum possible (all scored requirements at 5). It ignores unscored rows so partial assessments still compare fairly.
B13: Must gate = FAIL if the vendor scores below the Config pass threshold on any requirement marked 'Must'. A failing vendor is excluded regardless of %.
B14: To add a 5th+ vendor, insert paired Score/Weighted columns on the Assessment tab and extend the totals; or reuse the sheet per lot/package.
